terminate called after throwing an instance of 'std::exception'
  what():  std::exception
